FROM MAIN: APP RUNNING
FROM MAIN: right before
FROM CONTROLS: ZHICHEN AND FRIENDS
ROS MASTER is Offline
Unable to register with master node [http://localhost:11311]: master may not be running yet. Will keep trying.
[DEBUG] [1699541695.519110]: init_node, name[/controls], pid[4227]
[DEBUG] [1699541695.522998]: binding to 127.0.0.1 0
[DEBUG] [1699541695.526483]: bound to 127.0.0.1 43355
[DEBUG] [1699541695.530503]: ... service URL is rosrpc://localhost:43355
[DEBUG] [1699541695.533961]: [/controls/get_loggers]: new Service instance
[DEBUG] [1699541695.540138]: ... service URL is rosrpc://localhost:43355
[DEBUG] [1699541695.544827]: [/controls/set_logger_level]: new Service instance
Node Created
publisher done
shutdown request: [/controls] Reason: new node registered with same name
Traceback (most recent call last):
  File "main.py", line 31, in <module>
    c = Controls();
  File "/home/ubuntu/catkin_ws/src/mycobot_ros/mycobot_280/mycobot_280/scripts/controls.py", line 41, in __init__
    rospy.wait_for_service("release_servos")
  File "/opt/ros/melodic/lib/python2.7/dist-packages/rospy/impl/tcpros_service.py", line 166, in wait_for_service
    raise ROSInterruptException("rospy shutdown")
rospy.exceptions.ROSInterruptException: rospy shutdown
FROM MAIN: APP RUNNING
FROM MAIN: right before
FROM CONTROLS: ZHICHEN AND FRIENDS
ROS MASTER is Offline
Unable to register with master node [http://localhost:11311]: master may not be running yet. Will keep trying.
[DEBUG] [1699541695.563814]: init_node, name[/controls], pid[2920]
[DEBUG] [1699541695.569605]: binding to 127.0.0.1 0
[DEBUG] [1699541695.573232]: bound to 127.0.0.1 46289
[DEBUG] [1699541695.577129]: ... service URL is rosrpc://localhost:46289
[DEBUG] [1699541695.580461]: [/controls/get_loggers]: new Service instance
[DEBUG] [1699541695.587603]: ... service URL is rosrpc://localhost:46289
[DEBUG] [1699541695.591415]: [/controls/set_logger_level]: new Service instance
Node Created
publisher done
shutdown request: [/controls] Reason: new node registered with same name
Traceback (most recent call last):
  File "main.py", line 31, in <module>
    c = Controls();
  File "/home/ubuntu/catkin_ws/src/mycobot_ros/mycobot_280/mycobot_280/scripts/controls.py", line 41, in __init__
    rospy.wait_for_service("release_servos")
  File "/opt/ros/melodic/lib/python2.7/dist-packages/rospy/impl/tcpros_service.py", line 166, in wait_for_service
    raise ROSInterruptException("rospy shutdown")
rospy.exceptions.ROSInterruptException: rospy shutdown
FROM MAIN: APP RUNNING
FROM MAIN: right before
FROM CONTROLS: ZHICHEN AND FRIENDS
ROS MASTER is Offline
Unable to register with master node [http://localhost:11311]: master may not be running yet. Will keep trying.
[DEBUG] [1699541760.361461]: init_node, name[/controls], pid[5004]
[DEBUG] [1699541760.365857]: binding to 127.0.0.1 0
[DEBUG] [1699541760.369654]: bound to 127.0.0.1 34035
[DEBUG] [1699541760.376473]: ... service URL is rosrpc://localhost:34035
[DEBUG] [1699541760.380084]: [/controls/get_loggers]: new Service instance
[DEBUG] [1699541760.386716]: ... service URL is rosrpc://localhost:34035
[DEBUG] [1699541760.390183]: [/controls/set_logger_level]: new Service instance
Node Created
publisher done
[DEBUG] [1699541762.526640]: connecting to ('localhost', 44071)
servos released
Sets subscriber
Instance variables created
FROM MAIN: right after
 * Serving Flask app "main" (lazy loading)
 * Environment: production
   WARNING: This is a development server. Do not use it in a production deployment.
   Use a production WSGI server instead.
 * Debug mode: off
FROM MAIN: APP RUNNING
FROM MAIN: right before
FROM CONTROLS: ZHICHEN AND FRIENDS
ROS MASTER is Offline
Unable to register with master node [http://localhost:11311]: master may not be running yet. Will keep trying.
[DEBUG] [1699542607.574981]: init_node, name[/controls], pid[2415]
[DEBUG] [1699542607.579412]: binding to 127.0.0.1 0
[DEBUG] [1699542607.583179]: bound to 127.0.0.1 38575
[DEBUG] [1699542607.587525]: ... service URL is rosrpc://localhost:38575
[DEBUG] [1699542607.591324]: [/controls/get_loggers]: new Service instance
[DEBUG] [1699542607.597730]: ... service URL is rosrpc://localhost:38575
[DEBUG] [1699542607.601551]: [/controls/set_logger_level]: new Service instance
Node Created
publisher done
[DEBUG] [1699542609.442014]: connecting to ('localhost', 42701)
servos released
Sets subscriber
Instance variables created
FROM MAIN: right after
 * Serving Flask app "main" (lazy loading)
 * Environment: production
   WARNING: This is a development server. Do not use it in a production deployment.
   Use a production WSGI server instead.
 * Debug mode: off
[2023-11-09 23:13:30,014] ERROR in app: Exception on /show/ [GET]
Traceback (most recent call last):
  File "/usr/local/lib/python2.7/dist-packages/flask/app.py", line 2447, in wsgi_app
    response = self.full_dispatch_request()
  File "/usr/local/lib/python2.7/dist-packages/flask/app.py", line 1952, in full_dispatch_request
    rv = self.handle_user_exception(e)
  File "/usr/local/lib/python2.7/dist-packages/flask/app.py", line 1821, in handle_user_exception
    reraise(exc_type, exc_value, tb)
  File "/usr/local/lib/python2.7/dist-packages/flask/app.py", line 1950, in full_dispatch_request
    rv = self.dispatch_request()
  File "/usr/local/lib/python2.7/dist-packages/flask/app.py", line 1936, in dispatch_request
    return self.view_functions[rule.endpoint](**req.view_args)
  File "/home/ubuntu/robotic-arm/PublicApi/lightshow.py", line 35, in lightshow
    mc.set_color(red,green,blue)
  File "/usr/local/lib/python2.7/dist-packages/pymycobot/generate.py", line 602, in set_color
    return self._mesg(ProtocolCode.SET_COLOR, r, g, b)
  File "/usr/local/lib/python2.7/dist-packages/pymycobot/mycobot.py", line 83, in _mesg
    self._write(self._flatten(real_command))
  File "/usr/local/lib/python2.7/dist-packages/pymycobot/common.py", line 304, in write
    self._serial_port.flush()
  File "/usr/local/lib/python2.7/dist-packages/serial/serialposix.py", line 673, in flush
    termios.tcdrain(self.fd)
error: (4, 'Interrupted system call')
23:13:30.014 ERRO [main] Exception on /show/ [GET]
Traceback (most recent call last):
  File "/usr/local/lib/python2.7/dist-packages/flask/app.py", line 2447, in wsgi_app
    response = self.full_dispatch_request()
  File "/usr/local/lib/python2.7/dist-packages/flask/app.py", line 1952, in full_dispatch_request
    rv = self.handle_user_exception(e)
  File "/usr/local/lib/python2.7/dist-packages/flask/app.py", line 1821, in handle_user_exception
    reraise(exc_type, exc_value, tb)
  File "/usr/local/lib/python2.7/dist-packages/flask/app.py", line 1950, in full_dispatch_request
    rv = self.dispatch_request()
  File "/usr/local/lib/python2.7/dist-packages/flask/app.py", line 1936, in dispatch_request
    return self.view_functions[rule.endpoint](**req.view_args)
  File "/home/ubuntu/robotic-arm/PublicApi/lightshow.py", line 35, in lightshow
    mc.set_color(red,green,blue)
  File "/usr/local/lib/python2.7/dist-packages/pymycobot/generate.py", line 602, in set_color
    return self._mesg(ProtocolCode.SET_COLOR, r, g, b)
  File "/usr/local/lib/python2.7/dist-packages/pymycobot/mycobot.py", line 83, in _mesg
    self._write(self._flatten(real_command))
  File "/usr/local/lib/python2.7/dist-packages/pymycobot/common.py", line 304, in write
    self._serial_port.flush()
  File "/usr/local/lib/python2.7/dist-packages/serial/serialposix.py", line 673, in flush
    termios.tcdrain(self.fd)
error: (4, 'Interrupted system call')
23:13:30.154 WARN [rospy.internal] Unknown error initiating TCP/IP socket to localhost:42303 (http://localhost:34763/): Traceback (most recent call last):
  File "/opt/ros/melodic/lib/python2.7/dist-packages/rospy/impl/tcpros_base.py", line 560, in connect
    self.socket.connect((dest_addr, dest_port))
  File "/usr/lib/python2.7/socket.py", line 228, in meth
    return getattr(self._sock,name)(*args)
error: [Errno 111] Connection refused

FROM MAIN: APP RUNNING
FROM MAIN: right before
FROM CONTROLS: ZHICHEN AND FRIENDS
ROS MASTER is Offline
Unable to register with master node [http://localhost:11311]: master may not be running yet. Will keep trying.
[DEBUG] [1699542859.524642]: init_node, name[/controls], pid[4552]
[DEBUG] [1699542859.529622]: binding to 127.0.0.1 0
[DEBUG] [1699542859.533338]: bound to 127.0.0.1 36819
[DEBUG] [1699542859.538399]: ... service URL is rosrpc://localhost:36819
[DEBUG] [1699542859.541971]: [/controls/get_loggers]: new Service instance
[DEBUG] [1699542859.548669]: ... service URL is rosrpc://localhost:36819
[DEBUG] [1699542859.552982]: [/controls/set_logger_level]: new Service instance
Node Created
publisher done
[DEBUG] [1699542861.692669]: connecting to ('localhost', 43423)
servos released
Sets subscriber
Instance variables created
FROM MAIN: right after
 * Serving Flask app "main" (lazy loading)
 * Environment: production
   WARNING: This is a development server. Do not use it in a production deployment.
   Use a production WSGI server instead.
 * Debug mode: off
Traceback (most recent call last):
  File "main.py", line 68, in <module>
    app.run(host='10.194.29.175', port=5000, debug=False)
  File "/usr/local/lib/python2.7/dist-packages/flask/app.py", line 990, in run
    run_simple(host, port, self, **options)
  File "/usr/local/lib/python2.7/dist-packages/werkzeug/serving.py", line 1052, in run_simple
    inner()
  File "/usr/local/lib/python2.7/dist-packages/werkzeug/serving.py", line 1005, in inner
    fd=fd,
  File "/usr/local/lib/python2.7/dist-packages/werkzeug/serving.py", line 848, in make_server
    host, port, app, request_handler, passthrough_errors, ssl_context, fd=fd
  File "/usr/local/lib/python2.7/dist-packages/werkzeug/serving.py", line 740, in __init__
    HTTPServer.__init__(self, server_address, handler)
  File "/usr/lib/python2.7/SocketServer.py", line 420, in __init__
    self.server_bind()
  File "/usr/lib/python2.7/BaseHTTPServer.py", line 108, in server_bind
    SocketServer.TCPServer.server_bind(self)
  File "/usr/lib/python2.7/SocketServer.py", line 434, in server_bind
    self.socket.bind(self.server_address)
  File "/usr/lib/python2.7/socket.py", line 228, in meth
    return getattr(self._sock,name)(*args)
socket.error: [Errno 98] Address already in use
[DEBUG] [1699542861.771939]: TCPServer[36819] shutting down
FROM MAIN: APP RUNNING
FROM MAIN: right before
FROM CONTROLS: ZHICHEN AND FRIENDS
ROS MASTER is Offline
Unable to register with master node [http://localhost:11311]: master may not be running yet. Will keep trying.
[DEBUG] [1699543021.220003]: init_node, name[/controls], pid[2236]
[DEBUG] [1699543021.223880]: binding to 127.0.0.1 0
[DEBUG] [1699543021.227345]: bound to 127.0.0.1 40309
[DEBUG] [1699543021.231334]: ... service URL is rosrpc://localhost:40309
[DEBUG] [1699543021.234799]: [/controls/get_loggers]: new Service instance
[DEBUG] [1699543021.240753]: ... service URL is rosrpc://localhost:40309
[DEBUG] [1699543021.244109]: [/controls/set_logger_level]: new Service instance
Node Created
publisher done
[DEBUG] [1699543023.380637]: connecting to ('localhost', 32819)
servos released
Sets subscriber
Instance variables created
FROM MAIN: right after
 * Serving Flask app "main" (lazy loading)
 * Environment: production
   WARNING: This is a development server. Do not use it in a production deployment.
   Use a production WSGI server instead.
 * Debug mode: off
23:21:39.490 WARN [rospy.internal] Unknown error initiating TCP/IP socket to localhost:34737 (http://localhost:39383/): Traceback (most recent call last):
  File "/opt/ros/melodic/lib/python2.7/dist-packages/rospy/impl/tcpros_base.py", line 562, in connect
    self.read_header()
  File "/opt/ros/melodic/lib/python2.7/dist-packages/rospy/impl/tcpros_base.py", line 657, in read_header
    self._validate_header(read_ros_handshake_header(sock, self.read_buff, self.protocol.buff_size))
  File "/opt/ros/melodic/lib/python2.7/dist-packages/rosgraph/network.py", line 357, in read_ros_handshake_header
    d = sock.recv(buff_size)
error: [Errno 104] Connection reset by peer

FROM MAIN: APP RUNNING
FROM MAIN: right before
FROM CONTROLS: ZHICHEN AND FRIENDS
ROS MASTER is Offline
Unable to register with master node [http://localhost:11311]: master may not be running yet. Will keep trying.
[DEBUG] [1699543341.631323]: init_node, name[/controls], pid[4781]
[DEBUG] [1699543341.635774]: binding to 127.0.0.1 0
[DEBUG] [1699543341.639370]: bound to 127.0.0.1 34089
[DEBUG] [1699543341.643858]: ... service URL is rosrpc://localhost:34089
[DEBUG] [1699543341.647312]: [/controls/get_loggers]: new Service instance
[DEBUG] [1699543341.653746]: ... service URL is rosrpc://localhost:34089
[DEBUG] [1699543341.657182]: [/controls/set_logger_level]: new Service instance
Node Created
publisher done
[DEBUG] [1699543343.492563]: connecting to ('localhost', 33475)
servos released
Sets subscriber
Instance variables created
FROM MAIN: right after
 * Serving Flask app "main" (lazy loading)
 * Environment: production
   WARNING: This is a development server. Do not use it in a production deployment.
   Use a production WSGI server instead.
 * Debug mode: off
Traceback (most recent call last):
  File "main.py", line 68, in <module>
    app.run(host='10.194.29.175', port=5000, debug=False)
  File "/usr/local/lib/python2.7/dist-packages/flask/app.py", line 990, in run
    run_simple(host, port, self, **options)
  File "/usr/local/lib/python2.7/dist-packages/werkzeug/serving.py", line 1052, in run_simple
    inner()
  File "/usr/local/lib/python2.7/dist-packages/werkzeug/serving.py", line 1005, in inner
    fd=fd,
  File "/usr/local/lib/python2.7/dist-packages/werkzeug/serving.py", line 848, in make_server
    host, port, app, request_handler, passthrough_errors, ssl_context, fd=fd
  File "/usr/local/lib/python2.7/dist-packages/werkzeug/serving.py", line 740, in __init__
    HTTPServer.__init__(self, server_address, handler)
  File "/usr/lib/python2.7/SocketServer.py", line 420, in __init__
    self.server_bind()
  File "/usr/lib/python2.7/BaseHTTPServer.py", line 108, in server_bind
    SocketServer.TCPServer.server_bind(self)
  File "/usr/lib/python2.7/SocketServer.py", line 434, in server_bind
    self.socket.bind(self.server_address)
  File "/usr/lib/python2.7/socket.py", line 228, in meth
    return getattr(self._sock,name)(*args)
socket.error: [Errno 98] Address already in use
[DEBUG] [1699543343.573306]: connecting to localhost 35037
FROM MAIN: APP RUNNING
FROM MAIN: right before
FROM CONTROLS: ZHICHEN AND FRIENDS
ROS MASTER is Offline
Unable to register with master node [http://localhost:11311]: master may not be running yet. Will keep trying.
[DEBUG] [1699543572.081201]: init_node, name[/controls], pid[2055]
[DEBUG] [1699543572.088003]: binding to 127.0.0.1 0
[DEBUG] [1699543572.091738]: bound to 127.0.0.1 45447
[DEBUG] [1699543572.101003]: ... service URL is rosrpc://localhost:45447
[DEBUG] [1699543572.104533]: [/controls/get_loggers]: new Service instance
[DEBUG] [1699543572.111026]: ... service URL is rosrpc://localhost:45447
[DEBUG] [1699543572.114533]: [/controls/set_logger_level]: new Service instance
Node Created
publisher done
[DEBUG] [1699543573.949937]: connecting to ('localhost', 36387)
servos released
Sets subscriber
Instance variables created
FROM MAIN: right after
 * Serving Flask app "main" (lazy loading)
 * Environment: production
   WARNING: This is a development server. Do not use it in a production deployment.
   Use a production WSGI server instead.
 * Debug mode: off
FROM MAIN: APP RUNNING
FROM MAIN: right before
FROM CONTROLS: ZHICHEN AND FRIENDS
ROS MASTER is Offline
Unable to register with master node [http://localhost:11311]: master may not be running yet. Will keep trying.
[DEBUG] [1699548040.871456]: init_node, name[/controls], pid[2242]
[DEBUG] [1699548040.877222]: binding to 127.0.0.1 0
[DEBUG] [1699548040.880915]: bound to 127.0.0.1 43075
[DEBUG] [1699548040.886113]: ... service URL is rosrpc://localhost:43075
[DEBUG] [1699548040.891333]: [/controls/get_loggers]: new Service instance
[DEBUG] [1699548040.900143]: ... service URL is rosrpc://localhost:43075
[DEBUG] [1699548040.903569]: [/controls/set_logger_level]: new Service instance
Node Created
publisher done
[DEBUG] [1699548043.040410]: connecting to ('localhost', 37813)
servos released
Sets subscriber
Instance variables created
FROM MAIN: right after
 * Serving Flask app "main" (lazy loading)
 * Environment: production
   WARNING: This is a development server. Do not use it in a production deployment.
   Use a production WSGI server instead.
 * Debug mode: off
00:48:49.183 WARN [rospy.internal] Unknown error initiating TCP/IP socket to localhost:46191 (http://localhost:35575/): Traceback (most recent call last):
  File "/opt/ros/melodic/lib/python2.7/dist-packages/rospy/impl/tcpros_base.py", line 560, in connect
    self.socket.connect((dest_addr, dest_port))
  File "/usr/lib/python2.7/socket.py", line 228, in meth
    return getattr(self._sock,name)(*args)
error: [Errno 111] Connection refused

FROM MAIN: APP RUNNING
FROM MAIN: right before
FROM CONTROLS: ZHICHEN AND FRIENDS
ROS MASTER is Offline
Unable to register with master node [http://localhost:11311]: master may not be running yet. Will keep trying.
[DEBUG] [1699556186.669262]: init_node, name[/controls], pid[5484]
[DEBUG] [1699556186.673814]: binding to 127.0.0.1 0
[DEBUG] [1699556186.677478]: bound to 127.0.0.1 42695
[DEBUG] [1699556186.681632]: ... service URL is rosrpc://localhost:42695
[DEBUG] [1699556186.685632]: [/controls/get_loggers]: new Service instance
[DEBUG] [1699556186.692475]: ... service URL is rosrpc://localhost:42695
[DEBUG] [1699556186.696428]: [/controls/set_logger_level]: new Service instance
Node Created
publisher done
[DEBUG] [1699556188.841562]: connecting to ('localhost', 34551)
servos released
Sets subscriber
Instance variables created
FROM MAIN: right after
 * Serving Flask app "main" (lazy loading)
 * Environment: production
   WARNING: This is a development server. Do not use it in a production deployment.
   Use a production WSGI server instead.
 * Debug mode: off
FROM MAIN: APP RUNNING
FROM MAIN: right before
FROM CONTROLS: ZHICHEN AND FRIENDS
ROS MASTER is Offline
Unable to register with master node [http://localhost:11311]: master may not be running yet. Will keep trying.
[DEBUG] [1699557155.789535]: init_node, name[/controls], pid[7430]
[DEBUG] [1699557155.794316]: binding to 127.0.0.1 0
[DEBUG] [1699557155.799158]: bound to 127.0.0.1 40435
[DEBUG] [1699557155.806314]: ... service URL is rosrpc://localhost:40435
[DEBUG] [1699557155.809794]: [/controls/get_loggers]: new Service instance
[DEBUG] [1699557155.816105]: ... service URL is rosrpc://localhost:40435
[DEBUG] [1699557155.819775]: [/controls/set_logger_level]: new Service instance
Node Created
publisher done
[DEBUG] [1699557157.965525]: connecting to ('localhost', 41151)
servos released
Sets subscriber
Instance variables created
FROM MAIN: right after
 * Serving Flask app "main" (lazy loading)
 * Environment: production
   WARNING: This is a development server. Do not use it in a production deployment.
   Use a production WSGI server instead.
 * Debug mode: off
FROM MAIN: APP RUNNING
FROM MAIN: right before
FROM CONTROLS: ZHICHEN AND FRIENDS
ROS MASTER is Offline
Unable to register with master node [http://localhost:11311]: master may not be running yet. Will keep trying.
[DEBUG] [1699557578.677642]: init_node, name[/controls], pid[4148]
[DEBUG] [1699557578.681530]: binding to 127.0.0.1 0
[DEBUG] [1699557578.684972]: bound to 127.0.0.1 33801
[DEBUG] [1699557578.688832]: ... service URL is rosrpc://localhost:33801
[DEBUG] [1699557578.692046]: [/controls/get_loggers]: new Service instance
[DEBUG] [1699557578.698092]: ... service URL is rosrpc://localhost:33801
[DEBUG] [1699557578.702972]: [/controls/set_logger_level]: new Service instance
Node Created
publisher done
[DEBUG] [1699557581.159118]: connecting to ('localhost', 37137)
servos released
Sets subscriber
Instance variables created
FROM MAIN: right after
[DEBUG] [1699557581.213574]: connecting to localhost 39237
 * Serving Flask app "main" (lazy loading)
 * Environment: production
   WARNING: This is a development server. Do not use it in a production deployment.
   Use a production WSGI server instead.
 * Debug mode: off
03:25:29.085 WARN [rospy.internal] Unknown error initiating TCP/IP socket to localhost:39237 (http://localhost:36713/): Traceback (most recent call last):
  File "/opt/ros/melodic/lib/python2.7/dist-packages/rospy/impl/tcpros_base.py", line 562, in connect
    self.read_header()
  File "/opt/ros/melodic/lib/python2.7/dist-packages/rospy/impl/tcpros_base.py", line 657, in read_header
    self._validate_header(read_ros_handshake_header(sock, self.read_buff, self.protocol.buff_size))
AttributeError: 'NoneType' object has no attribute 'buff_size'

FROM MAIN: APP RUNNING
FROM MAIN: right before
FROM CONTROLS: ZHICHEN AND FRIENDS
ROS MASTER is Offline
Unable to register with master node [http://localhost:11311]: master may not be running yet. Will keep trying.
[DEBUG] [1699558254.442518]: init_node, name[/controls], pid[2294]
[DEBUG] [1699558254.446640]: binding to 127.0.0.1 0
[DEBUG] [1699558254.450576]: bound to 127.0.0.1 45977
[DEBUG] [1699558254.464880]: ... service URL is rosrpc://localhost:45977
[DEBUG] [1699558254.468475]: [/controls/get_loggers]: new Service instance
[DEBUG] [1699558254.474841]: ... service URL is rosrpc://localhost:45977
[DEBUG] [1699558254.478371]: [/controls/set_logger_level]: new Service instance
Node Created
publisher done
[DEBUG] [1699558256.632618]: connecting to ('localhost', 44887)
servos released
Sets subscriber
Instance variables created
FROM MAIN: right after
 * Serving Flask app "main" (lazy loading)
 * Environment: production
   WARNING: This is a development server. Do not use it in a production deployment.
   Use a production WSGI server instead.
 * Debug mode: off
03:31:33.289 WARN [rospy.internal] Unknown error initiating TCP/IP socket to localhost:34141 (http://localhost:36039/): Traceback (most recent call last):
  File "/opt/ros/melodic/lib/python2.7/dist-packages/rospy/impl/tcpros_base.py", line 560, in connect
    self.socket.connect((dest_addr, dest_port))
AttributeError: 'NoneType' object has no attribute 'connect'

